<?xml version="1.0" ?>
<robot name="mobile_manipulator">
  <ros2_control name="HC_control" type="system">
    <hardware>
      <plugin>gazebo_ros2_control/GazeboSystem</plugin>
      <plugin>mock_components/GenericSystem</plugin>
      <param name="fake_sensor_commands">False</param>
      <param name="state_following_offset">0.0</param>
    </hardware>
    <joint name="fl_joint">
      <command_interface name="velocity"/>
      <state_interface name="position">
        <param name="initial_value">0.0</param>
      </state_interface>
      <state_interface name="velocity"/>
      <state_interface name="effort"/>
    </joint>
    <joint name="fr_joint">
      <command_interface name="velocity"/>
      <state_interface name="position">
        <param name="initial_value">0.0</param>
      </state_interface>
      <state_interface name="velocity"/>
      <state_interface name="effort"/>
    </joint>
    <joint name="rl_bracket_joint">
      <state_interface name="position">
        <param name="initial_value">0.0</param>
      </state_interface>
      <state_interface name="velocity"/>
      <state_interface name="effort"/>
    </joint>
    <joint name="rl_wheel_joint">
      <state_interface name="position">
        <param name="initial_value">0.0</param>
      </state_interface>
      <state_interface name="velocity"/>
      <state_interface name="effort"/>
    </joint>
    <joint name="rr_bracket_joint">
      <state_interface name="position">
        <param name="initial_value">0.0</param>
      </state_interface>
      <state_interface name="velocity"/>
      <state_interface name="effort"/>
    </joint>
    <joint name="rr_wheel_joint">
      <state_interface name="position">
        <param name="initial_value">0.0</param>
      </state_interface>
      <state_interface name="velocity"/>
      <state_interface name="effort"/>
    </joint>
    <joint name="arm_joint_1">
      <command_interface name="position">
        <param name="min">-2.69</param>
        <param name="max">2.69</param>
      </command_interface>
      <state_interface name="position">
        <param name="initial_value">0.0</param>
      </state_interface>
      <state_interface name="velocity"/>
      <state_interface name="effort"/>
    </joint>
    <joint name="arm_joint_2">
      <command_interface name="position">
        <param name="min">-2.69</param>
        <param name="max">2.36</param>
      </command_interface>
      <state_interface name="position">
        <param name="initial_value">0.0</param>
      </state_interface>
      <state_interface name="velocity"/>
      <state_interface name="effort"/>
    </joint>
    <joint name="arm_joint_3">
      <command_interface name="position">
        <param name="min">-2.69</param>
        <param name="max">2.69</param>
      </command_interface>
      <state_interface name="position">
        <param name="initial_value">0.0</param>
      </state_interface>
      <state_interface name="velocity"/>
      <state_interface name="effort"/>
    </joint>
    <joint name="arm_joint_4">
      <command_interface name="position">
        <param name="min">-2.59</param>
        <param name="max">2.59</param>
      </command_interface>
      <state_interface name="position">
        <param name="initial_value">0.0</param>
      </state_interface>
      <state_interface name="velocity"/>
      <state_interface name="effort"/>
    </joint>
    <joint name="arm_joint_5">
      <command_interface name="position">
        <param name="min">-2.57</param>
        <param name="max">2.57</param>
      </command_interface>
      <state_interface name="position">
        <param name="initial_value">0.0</param>
      </state_interface>
      <state_interface name="velocity"/>
      <state_interface name="effort"/>
    </joint>
    <joint name="arm_joint_6">
      <command_interface name="position">
        <param name="min">-2.59</param>
        <param name="max">2.59</param>
      </command_interface>
      <state_interface name="position">
        <param name="initial_value">0.0</param>
      </state_interface>
      <state_interface name="velocity"/>
      <state_interface name="effort"/>
    </joint>
    <joint name="right_finger_bottom_joint">
      <command_interface name="position">
        <param name="min">-0.9</param>
        <param name="max">0.96</param>
      </command_interface>
      <state_interface name="position">
        <param name="initial_value">0.0</param>
      </state_interface>
      <state_interface name="velocity"/>
      <state_interface name="effort"/>
    </joint>
    <joint name="right_finger_tip_joint">
      <param name="mimic">right_finger_bottom_joint</param>
      <param name="multiplier">-1.0</param>
      <command_interface name="position"/>
      <state_interface name="position"/>
      <state_interface name="velocity"/>
      <state_interface name="effort"/>
    </joint>
    <joint name="left_finger_bottom_joint">
      <param name="mimic">right_finger_bottom_joint</param>
      <param name="multiplier">1.0</param>
      <command_interface name="position"/>
      <state_interface name="position"/>
      <state_interface name="velocity"/>
      <state_interface name="effort"/>
    </joint>
    <joint name="left_finger_tip_joint">
      <param name="mimic">right_finger_bottom_joint</param>
      <param name="multiplier">-1.0</param>
      <command_interface name="position"/>
      <state_interface name="position"/>
      <state_interface name="velocity"/>
      <state_interface name="effort"/>
    </joint>
  </ros2_control>
  <transmission name="fl_joint_transmission">
    <type>transmission_interface/SimpleTransmission</type>
    <joint name="fl_joint">
      <hardwareInterface>hardware_interface/VelocityJointInterface</hardwareInterface>
    </joint>
    <actuator name="fl_wheel_motor">
      <mechanicalReduction>1</mechanicalReduction>
    </actuator>
  </transmission>
  <transmission name="fr_joint_transmission">
    <type>transmission_interface/SimpleTransmission</type>
    <joint name="fr_joint">
      <hardwareInterface>hardware_interface/VelocityJointInterface</hardwareInterface>
    </joint>
    <actuator name="fr_wheel_motor">
      <mechanicalReduction>1</mechanicalReduction>
    </actuator>
  </transmission>
  <transmission name="arm_joint_1_transmission">
    <type>transmission_interface/SimpleTransmission</type>
    <joint name="arm_joint_1">
      <hardwareInterface>hardware_interface/PositionJointInterface</hardwareInterface>
    </joint>
    <actuator name="arm_joint_1_motor">
      <mechanicalReduction>1</mechanicalReduction>
    </actuator>
  </transmission>
  <transmission name="arm_joint_2_transmission">
    <type>transmission_interface/SimpleTransmission</type>
    <joint name="arm_joint_2">
      <hardwareInterface>hardware_interface/PositionJointInterface</hardwareInterface>
    </joint>
    <actuator name="arm_joint_2_motor">
      <mechanicalReduction>1</mechanicalReduction>
    </actuator>
  </transmission>
  <transmission name="arm_joint_3_transmission">
    <type>transmission_interface/SimpleTransmission</type>
    <joint name="arm_joint_3">
      <hardwareInterface>hardware_interface/PositionJointInterface</hardwareInterface>
    </joint>
    <actuator name="arm_joint_3_motor">
      <mechanicalReduction>1</mechanicalReduction>
    </actuator>
  </transmission>
  <transmission name="arm_joint_4_transmission">
    <type>transmission_interface/SimpleTransmission</type>
    <joint name="arm_joint_4">
      <hardwareInterface>hardware_interface/PositionJointInterface</hardwareInterface>
    </joint>
    <actuator name="arm_joint_4_motor">
      <mechanicalReduction>1</mechanicalReduction>
    </actuator>
  </transmission>
  <transmission name="arm_joint_5_transmission">
    <type>transmission_interface/SimpleTransmission</type>
    <joint name="arm_joint_5">
      <hardwareInterface>hardware_interface/PositionJointInterface</hardwareInterface>
    </joint>
    <actuator name="arm_joint_5_motor">
      <mechanicalReduction>1</mechanicalReduction>
    </actuator>
  </transmission>
  <transmission name="arm_joint_6_transmission">
    <type>transmission_interface/SimpleTransmission</type>
    <joint name="arm_joint_6">
      <hardwareInterface>hardware_interface/PositionJointInterface</hardwareInterface>
    </joint>
    <actuator name="arm_joint_6_motor">
      <mechanicalReduction>1</mechanicalReduction>
    </actuator>
  </transmission>
  <transmission name="right_finger_bottom_joint_transmission">
    <type>transmission_interface/SimpleTransmission</type>
    <joint name="right_finger_bottom_joint">
      <hardwareInterface>hardware_interface/PositionJointInterface</hardwareInterface>
    </joint>
    <actuator name="right_finger_bottom_joint_motor">
      <mechanicalReduction>1</mechanicalReduction>
      <hardwareInterface>hardware_interface/PositionJointInterface</hardwareInterface>
    </actuator>
  </transmission>
  <gazebo>
    <plugin filename="libroboticsgroup_gazebo_mimic_joint_plugin.so" name="mimic_right_finger_tip_joint">
      <joint>right_finger_bottom_joint</joint>
      <mimicJoint>right_finger_tip_joint</mimicJoint>
      <multiplier>-0.676</multiplier>
      <offset>0.149</offset>
      <maxEffort>5.0</maxEffort>
      <hasPID/>
    </plugin>
    <plugin filename="libroboticsgroup_gazebo_mimic_joint_plugin.so" name="mimic_left_finger_bottom_joint">
      <joint>right_finger_bottom_joint</joint>
      <mimicJoint>left_finger_bottom_joint</mimicJoint>
      <multiplier>-1.0</multiplier>
      <offset>0.0</offset>
      <maxEffort>5.0</maxEffort>
      <hasPID/>
    </plugin>
    <plugin filename="libroboticsgroup_gazebo_mimic_joint_plugin.so" name="mimic_left_finger_tip_joint">
      <joint>right_finger_bottom_joint</joint>
      <mimicJoint>left_finger_tip_joint</mimicJoint>
      <multiplier>-0.676</multiplier>
      <offset>0.149</offset>
      <maxEffort>5.0</maxEffort>
      <hasPID/>
    </plugin>
    <plugin filename="libgazebo_grasp_fix.so" name="gazebo_grasp_fix">
      <arm>
        <arm_name>mobile_manipulator_gripper</arm_name>
        <palm_link>end_effector_link</palm_link>
        <gripper_link>right_finger_dist_link</gripper_link>
        <gripper_link>left_finger_dist_link</gripper_link>
      </arm>
      <forces_angle_tolerance>100</forces_angle_tolerance>
      <update_rate>10</update_rate>
      <grip_count_threshold>3</grip_count_threshold>
      <max_grip_count>10</max_grip_count>
      <release_tolerance>0.001</release_tolerance>
      <disable_collisions_on_attach>false</disable_collisions_on_attach>
      <contact_topic>__default_topic__</contact_topic>
    </plugin>
  </gazebo>
  <link name="base_link">
    <inertial>
      <mass value="0.0001"/>
      <origin rpy="0 0 0" xyz="0 0 0"/>
      <inertia ixx="1e-6" ixy="0" ixz="0" iyy="1e-6" iyz="0" izz="1e-6"/>
    </inertial>
    <collision>
      <origin rpy="0 0 0" xyz="0 0 0"/>
      <geometry>
        <sphere radius="0.001"/>
      </geometry>
    </collision>
  </link>
  <joint name="base_body_joint" type="fixed">
    <origin rpy="0 0 0" xyz="0 0 0.29386"/>
    <parent link="base_link"/>
    <child link="base_body"/>
  </joint>
  <link name="base_body">
    <visual>
      <origin rpy="0 0 0" xyz="0 0 0"/>
      <geometry>
        <mesh filename="/home/research/hc_ws/install/mobile_manipulator/share/mobile_manipulator/meshes/base/base_body.stl"/>
      </geometry>
      <material name="">
        <color rgba="1 1 1 1"/>
      </material>
    </visual>
    <collision>
      <origin rpy="0 0 0" xyz="0 0 0"/>
      <geometry>
        <mesh filename="/home/research/hc_ws/install/mobile_manipulator/share/mobile_manipulator/meshes/base/base_body.stl"/>
      </geometry>
    </collision>
    <inertial>
      <origin rpy="0 0 0" xyz="0 0 0"/>
      <mass value="24.3948952632956"/>
      <inertia ixx="0.4663503691671374" ixy="0.0" ixz="0.0" iyy="0.4663503691671374" iyz="0.0" izz="0.6505305403545494"/>
    </inertial>
  </link>
  <joint name="fl_joint" type="continuous">
    <origin rpy="-1.5707963267948966 0 0" xyz="0.05 0.127547 -0.23636000000000001 "/>
    <parent link="base_body"/>
    <child link="fl_wheel"/>
    <axis xyz="0 0 1"/>
  </joint>
  <link name="fl_wheel">
    <visual>
      <origin rpy="1.5707963267948966 0 0" xyz="0 0 0"/>
      <geometry>
        <mesh filename="/home/research/hc_ws/install/mobile_manipulator/share/mobile_manipulator/meshes/base/front_wheel.stl"/>
      </geometry>
      <material name="">
        <color rgba="0.5 0.5 0.5 1"/>
      </material>
    </visual>
    <collision>
      <origin rpy="1.5707963267948966 0 0" xyz="0 0 0"/>
      <geometry>
        <mesh filename="/home/research/hc_ws/install/mobile_manipulator/share/mobile_manipulator/meshes/base/front_wheel.stl"/>
      </geometry>
    </collision>
    <inertial>
      <origin rpy="1.5707963267948966 0 0" xyz="0 0 0"/>
      <mass value="1.0"/>
      <inertia ixx="0.0013537303216705255" ixy="0.0" ixz="0.0" iyy="0.0013537303216705255" iyz="0.0" izz="0.001653125"/>
    </inertial>
  </link>
  <joint name="fr_joint" type="continuous">
    <origin rpy="1.5707963267948966 0 0" xyz="0.05 -0.127547 -0.23636000000000001"/>
    <parent link="base_body"/>
    <child link="fr_wheel"/>
    <axis xyz="0 0 1"/>
  </joint>
  <link name="fr_wheel">
    <visual>
      <origin rpy="-1.5707963267948966 0 0" xyz="0 0 0"/>
      <geometry>
        <mesh filename="/home/research/hc_ws/install/mobile_manipulator/share/mobile_manipulator/meshes/base/front_wheel.stl"/>
      </geometry>
      <material name="">
        <color rgba="0.5 0.5 0.5 1"/>
      </material>
    </visual>
    <collision>
      <origin rpy="-1.5707963267948966 0 0" xyz="0 0 0"/>
      <geometry>
        <mesh filename="/home/research/hc_ws/install/mobile_manipulator/share/mobile_manipulator/meshes/base/front_wheel.stl"/>
      </geometry>
    </collision>
    <inertial>
      <origin rpy="-1.5707963267948966 0 0" xyz="0 0 0"/>
      <mass value="1.0"/>
      <inertia ixx="0.0013537303216705255" ixy="0.0" ixz="0.0" iyy="0.0013537303216705255" iyz="0.0" izz="0.001653125"/>
    </inertial>
  </link>
  <joint name="rl_bracket_joint" type="continuous">
    <origin rpy="0 0 0" xyz="-0.17043 0.125 -0.21606000000000003"/>
    <parent link="base_body"/>
    <child link="rl_bracket"/>
    <axis xyz="0 0 1"/>
  </joint>
  <link name="rl_bracket">
    <visual>
      <origin rpy="0 0 1.5707963267948966" xyz="0 0 0"/>
      <geometry>
        <mesh filename="/home/research/hc_ws/install/mobile_manipulator/share/mobile_manipulator/meshes/base/rear_wheel_bracket.stl"/>
      </geometry>
      <material name="">
        <color rgba="0.5 0.5 0.5 1"/>
      </material>
    </visual>
    <collision>
      <origin rpy="0 0 1.5707963267948966" xyz="0 0 0"/>
      <geometry>
        <mesh filename="/home/research/hc_ws/install/mobile_manipulator/share/mobile_manipulator/meshes/base/rear_wheel_bracket.stl"/>
      </geometry>
    </collision>
    <inertial>
      <origin rpy="0 0 1.5707963267948966" xyz="0 0 0"/>
      <mass value="0.2"/>
      <inertia ixx="3.9201499999999994e-05" ixy="0.0" ixz="0.0" iyy="3.9201499999999994e-05" iyz="0.0" izz="1e-05"/>
    </inertial>
  </link>
  <joint name="rl_wheel_joint" type="continuous">
    <origin rpy="-1.5707963267948966 0 0" xyz="-0.027 0 -0.0453"/>
    <parent link="rl_bracket"/>
    <child link="rl_wheel"/>
    <axis xyz="0 0 1"/>
  </joint>
  <link name="rl_wheel">
    <visual>
      <origin rpy="0 -1.5707963267948966 0" xyz="0 0 0"/>
      <geometry>
        <mesh filename="/home/research/hc_ws/install/mobile_manipulator/share/mobile_manipulator/meshes/base/rear_wheel.stl"/>
      </geometry>
      <material name="">
        <color rgba="0.5 0.5 0.5 1"/>
      </material>
    </visual>
    <collision>
      <origin rpy="0 -1.5707963267948966 0" xyz="0 0 0"/>
      <geometry>
        <mesh filename="/home/research/hc_ws/install/mobile_manipulator/share/mobile_manipulator/meshes/base/rear_wheel.stl"/>
      </geometry>
    </collision>
    <inertial>
      <origin rpy="0 -1.5707963267948966 0" xyz="0 0 0"/>
      <mass value="0.1"/>
      <inertia ixx="3.05634375981929e-05" ixy="0.0" ixz="0.0" iyy="3.05634375981929e-05" iyz="0.0" izz="5.281250000000001e-05"/>
    </inertial>
  </link>
  <joint name="rr_bracket_joint" type="continuous">
    <origin rpy="0 0 0" xyz="-0.17043 -0.125 -0.21606000000000003"/>
    <parent link="base_body"/>
    <child link="rr_bracket"/>
    <axis xyz="0 0 1"/>
  </joint>
  <link name="rr_bracket">
    <visual>
      <origin rpy="0 0 1.5707963267948966" xyz="0 0 0"/>
      <geometry>
        <mesh filename="/home/research/hc_ws/install/mobile_manipulator/share/mobile_manipulator/meshes/base/rear_wheel_bracket.stl"/>
      </geometry>
      <material name="">
        <color rgba="0.5 0.5 0.5 1"/>
      </material>
    </visual>
    <collision>
      <origin rpy="0 0 1.5707963267948966" xyz="0 0 0"/>
      <geometry>
        <mesh filename="/home/research/hc_ws/install/mobile_manipulator/share/mobile_manipulator/meshes/base/rear_wheel_bracket.stl"/>
      </geometry>
    </collision>
    <inertial>
      <origin rpy="0 0 1.5707963267948966" xyz="0 0 0"/>
      <mass value="0.2"/>
      <inertia ixx="3.9201499999999994e-05" ixy="0.0" ixz="0.0" iyy="3.9201499999999994e-05" iyz="0.0" izz="1e-05"/>
    </inertial>
  </link>
  <joint name="rr_wheel_joint" type="continuous">
    <origin rpy="1.5707963267948966 0 0" xyz="-0.027 0 -0.0453"/>
    <parent link="rr_bracket"/>
    <child link="rr_wheel"/>
    <axis xyz="0 0 1"/>
  </joint>
  <link name="rr_wheel">
    <visual>
      <origin rpy="0 1.5707963267948966 0" xyz="0 0 0"/>
      <geometry>
        <mesh filename="/home/research/hc_ws/install/mobile_manipulator/share/mobile_manipulator/meshes/base/rear_wheel.stl"/>
      </geometry>
      <material name="">
        <color rgba="0.5 0.5 0.5 1"/>
      </material>
    </visual>
    <collision>
      <origin rpy="0 1.5707963267948966 0" xyz="0 0 0"/>
      <geometry>
        <mesh filename="/home/research/hc_ws/install/mobile_manipulator/share/mobile_manipulator/meshes/base/rear_wheel.stl"/>
      </geometry>
    </collision>
    <inertial>
      <origin rpy="0 1.5707963267948966 0" xyz="0 0 0"/>
      <mass value="0.1"/>
      <inertia ixx="3.05634375981929e-05" ixy="0.0" ixz="0.0" iyy="3.05634375981929e-05" iyz="0.0" izz="5.281250000000001e-05"/>
    </inertial>
  </link>
  <joint name="laser_joint" type="fixed">
    <origin rpy="0 0 0" xyz="0.04517 0 -0.1053"/>
    <parent link="base_body"/>
    <child link="laser_Link"/>
  </joint>
  <link name="laser_Link">
    <visual>
      <origin rpy="0 0 0" xyz="0 0 0"/>
      <geometry>
        <mesh filename="/home/research/hc_ws/install/mobile_manipulator/share/mobile_manipulator/meshes/base/lidar.stl"/>
      </geometry>
      <material name="">
        <color rgba="1 0.6 0 1"/>
      </material>
    </visual>
    <collision>
      <origin rpy="0 0 0" xyz="0 0 0"/>
      <geometry>
        <mesh filename="/home/research/hc_ws/install/mobile_manipulator/share/mobile_manipulator/meshes/base/lidar.stl"/>
      </geometry>
    </collision>
    <inertial>
      <origin rpy="0 0 0" xyz="0 0 0"/>
      <mass value="0.1"/>
      <inertia ixx="4.116358333333333e-05" ixy="0.0" ixz="0.0" iyy="4.116358333333333e-05" iyz="0.0" izz="7.56605e-05"/>
    </inertial>
  </link>
  <joint name="base_camera_joint" type="fixed">
    <origin rpy="1.5707963267948966 0 1.5707963267948966" xyz="0.115 0 -0.04565"/>
    <parent link="base_body"/>
    <child link="base_camera"/>
  </joint>
  <link name="base_camera">
    <visual>
      <!-- <origin rpy="1.5707963267948966 0 1.5707963267948966" xyz="0 0 0"/> -->
      <origin rpy="0 0 0" xyz="0 0 0"/>
      <geometry>
        <mesh filename="/home/research/hc_ws/install/mobile_manipulator/share/mobile_manipulator/meshes/base/d435.dae"/>
      </geometry>
      <material name="aluminum">
        <color rgba="0.5 0.5 0.5 1"/>
      </material>
    </visual>
    <collision>
      <origin rpy="0 0 0" xyz="0 0 0"/>
      <geometry>
        <mesh filename="/home/research/hc_ws/install/mobile_manipulator/share/mobile_manipulator/meshes/base/d435.dae"/>
      </geometry>
    </collision>
    <inertial>
      <origin rpy="0 0 0" xyz="0 0 0"/>
      <mass value="0.072"/>
      <inertia ixx="7.515015e-06" ixy="0.0" ixz="0.0" iyy="5.234999999999999e-05" iyz="0.0" izz="5.236501499999999e-05"/>
    </inertial>
  </link>
  <joint name="base_camera_depth_joint" type="fixed">
    <origin rpy="0 0 0" xyz="-0.00595 0.0175 0"/>
    <parent link="base_camera"/>
    <child link="base_camera_depth_frame"/>
  </joint>
  <link name="base_camera_depth_frame">
    <inertial>
      <origin rpy="0 0 0" xyz="0 0 0"/>
      <mass value="0.01"/>
      <inertia ixx="1e-5" ixy="0" ixz="0" iyy="1e-5" iyz="0" izz="1e-5"/>
    </inertial>
    <visual>
      <origin rpy="0 0 0" xyz="0 0 0"/>
      <geometry>
        <sphere radius="0.001"/>
      </geometry>
    </visual>
    <collision>
      <origin rpy="0 0 0" xyz="0 0 0"/>
      <geometry>
        <sphere radius="0.001"/>
      </geometry>
    </collision>
  </link>
  <joint name="base_camera_depth_optical_joint" type="fixed">
    <origin rpy="-1.5707963267948966 0 -1.5707963267948966" xyz="0 0 0"/>
    <parent link="base_camera_depth_frame"/>
    <child link="base_camera_depth_optical_frame"/>
  </joint>
  <link name="base_camera_depth_optical_frame">
    <inertial>
      <origin rpy="0 0 0" xyz="0 0 0"/>
      <mass value="0.01"/>
      <inertia ixx="1e-5" ixy="0" ixz="0" iyy="1e-5" iyz="0" izz="1e-5"/>
    </inertial>
    <visual>
      <origin rpy="0 0 0" xyz="0 0 0"/>
      <geometry>
        <sphere radius="0.001"/>
      </geometry>
    </visual>
    <collision>
      <origin rpy="0 0 0" xyz="0 0 0"/>
      <geometry>
        <sphere radius="0.001"/>
      </geometry>
    </collision>
  </link>
  <joint name="base_camera_infra1_joint" type="fixed">
    <origin rpy="0 0 0" xyz="0 0.0 0"/>
    <parent link="base_camera_depth_frame"/>
    <child link="base_camera_infra1_frame"/>
  </joint>
  <link name="base_camera_infra1_frame">
    <inertial>
      <origin rpy="0 0 0" xyz="0 0 0"/>
      <mass value="0.01"/>
      <inertia ixx="1e-5" ixy="0" ixz="0" iyy="1e-5" iyz="0" izz="1e-5"/>
    </inertial>
    <visual>
      <origin rpy="0 0 0" xyz="0 0 0"/>
      <geometry>
        <sphere radius="0.001"/>
      </geometry>
    </visual>
    <collision>
      <origin rpy="0 0 0" xyz="0 0 0"/>
      <geometry>
        <sphere radius="0.001"/>
      </geometry>
    </collision>
  </link>
  <joint name="base_camera_infra1_optical_joint" type="fixed">
    <origin rpy="-1.5707963267948966 0 -1.5707963267948966" xyz="0 0 0"/>
    <parent link="base_camera_infra1_frame"/>
    <child link="base_camera_infra1_optical_frame"/>
  </joint>
  <link name="base_camera_infra1_optical_frame">
    <inertial>
      <origin rpy="0 0 0" xyz="0 0 0"/>
      <mass value="0.01"/>
      <inertia ixx="1e-5" ixy="0" ixz="0" iyy="1e-5" iyz="0" izz="1e-5"/>
    </inertial>
    <visual>
      <origin rpy="0 0 0" xyz="0 0 0"/>
      <geometry>
        <sphere radius="0.001"/>
      </geometry>
    </visual>
    <collision>
      <origin rpy="0 0 0" xyz="0 0 0"/>
      <geometry>
        <sphere radius="0.001"/>
      </geometry>
    </collision>
  </link>
  <joint name="base_camera_infra2_joint" type="fixed">
    <origin rpy="0 0 0" xyz="0 -0.05 0"/>
    <parent link="base_camera_depth_frame"/>
    <child link="base_camera_infra2_frame"/>
  </joint>
  <link name="base_camera_infra2_frame">
    <inertial>
      <origin rpy="0 0 0" xyz="0 0 0"/>
      <mass value="0.01"/>
      <inertia ixx="1e-5" ixy="0" ixz="0" iyy="1e-5" iyz="0" izz="1e-5"/>
    </inertial>
    <visual>
      <origin rpy="0 0 0" xyz="0 0 0"/>
      <geometry>
        <sphere radius="0.001"/>
      </geometry>
    </visual>
    <collision>
      <origin rpy="0 0 0" xyz="0 0 0"/>
      <geometry>
        <sphere radius="0.001"/>
      </geometry>
    </collision>
  </link>
  <joint name="base_camera_infra2_optical_joint" type="fixed">
    <origin rpy="-1.5707963267948966 0 -1.5707963267948966" xyz="0 0 0"/>
    <parent link="base_camera_infra2_frame"/>
    <child link="base_camera_infra2_optical_frame"/>
  </joint>
  <link name="base_camera_infra2_optical_frame">
    <inertial>
      <origin rpy="0 0 0" xyz="0 0 0"/>
      <mass value="0.01"/>
      <inertia ixx="1e-5" ixy="0" ixz="0" iyy="1e-5" iyz="0" izz="1e-5"/>
    </inertial>
    <visual>
      <origin rpy="0 0 0" xyz="0 0 0"/>
      <geometry>
        <sphere radius="0.001"/>
      </geometry>
    </visual>
    <collision>
      <origin rpy="0 0 0" xyz="0 0 0"/>
      <geometry>
        <sphere radius="0.001"/>
      </geometry>
    </collision>
  </link>
  <joint name="base_camera_color_joint" type="fixed">
    <origin rpy="0 0 0" xyz="0 0.015 0"/>
    <parent link="base_camera_depth_frame"/>
    <child link="base_camera_color_frame"/>
  </joint>
  <link name="base_camera_color_frame">
    <inertial>
      <origin rpy="0 0 0" xyz="0 0 0"/>
      <mass value="0.01"/>
      <inertia ixx="1e-5" ixy="0" ixz="0" iyy="1e-5" iyz="0" izz="1e-5"/>
    </inertial>
    <visual>
      <origin rpy="0 0 0" xyz="0 0 0"/>
      <geometry>
        <sphere radius="0.001"/>
      </geometry>
    </visual>
    <collision>
      <origin rpy="0 0 0" xyz="0 0 0"/>
      <geometry>
        <sphere radius="0.001"/>
      </geometry>
    </collision>
  </link>
  <joint name="base_camera_color_optical_joint" type="fixed">
    <origin rpy="-1.5707963267948966 0 -1.5707963267948966" xyz="0 0 0"/>
    <parent link="base_camera_color_frame"/>
    <child link="base_camera_color_optical_frame"/>
  </joint>
  <link name="base_camera_color_optical_frame">
    <inertial>
      <origin rpy="0 0 0" xyz="0 0 0"/>
      <mass value="0.01"/>
      <inertia ixx="1e-5" ixy="0" ixz="0" iyy="1e-5" iyz="0" izz="1e-5"/>
    </inertial>
    <visual>
      <origin rpy="0 0 0" xyz="0 0 0"/>
      <geometry>
        <sphere radius="0.001"/>
      </geometry>
    </visual>
    <collision>
      <origin rpy="0 0 0" xyz="0 0 0"/>
      <geometry>
        <sphere radius="0.001"/>
      </geometry>
    </collision>
  </link>
  <joint name="base_camera_accel_joint" type="fixed">
    <origin rpy="0 0 0" xyz="-0.01174 -0.00552 0.0051"/>
    <parent link="base_camera_depth_frame"/>
    <child link="base_camera_accel_frame"/>
  </joint>
  <link name="base_camera_accel_frame">
    <inertial>
      <origin rpy="0 0 0" xyz="0 0 0"/>
      <mass value="0.01"/>
      <inertia ixx="1e-5" ixy="0" ixz="0" iyy="1e-5" iyz="0" izz="1e-5"/>
    </inertial>
    <visual>
      <origin rpy="0 0 0" xyz="0 0 0"/>
      <geometry>
        <sphere radius="0.001"/>
      </geometry>
    </visual>
    <collision>
      <origin rpy="0 0 0" xyz="0 0 0"/>
      <geometry>
        <sphere radius="0.001"/>
      </geometry>
    </collision>
  </link>
  <joint name="base_camera_accel_optical_joint" type="fixed">
    <origin rpy="-1.5707963267948966 0 -1.5707963267948966" xyz="0 0 0"/>
    <parent link="base_camera_accel_frame"/>
    <child link="base_camera_accel_optical_frame"/>
  </joint>
  <link name="base_camera_accel_optical_frame">
    <inertial>
      <origin rpy="0 0 0" xyz="0 0 0"/>
      <mass value="0.01"/>
      <inertia ixx="1e-5" ixy="0" ixz="0" iyy="1e-5" iyz="0" izz="1e-5"/>
    </inertial>
    <visual>
      <origin rpy="0 0 0" xyz="0 0 0"/>
      <geometry>
        <sphere radius="0.001"/>
      </geometry>
    </visual>
    <collision>
      <origin rpy="0 0 0" xyz="0 0 0"/>
      <geometry>
        <sphere radius="0.001"/>
      </geometry>
    </collision>
  </link>
  <joint name="base_camera_gyro_joint" type="fixed">
    <origin rpy="0 0 0" xyz="-0.01174 -0.00552 0.0051"/>
    <parent link="base_camera_depth_frame"/>
    <child link="base_camera_gyro_frame"/>
  </joint>
  <link name="base_camera_gyro_frame">
    <inertial>
      <origin rpy="0 0 0" xyz="0 0 0"/>
      <mass value="0.01"/>
      <inertia ixx="1e-5" ixy="0" ixz="0" iyy="1e-5" iyz="0" izz="1e-5"/>
    </inertial>
    <visual>
      <origin rpy="0 0 0" xyz="0 0 0"/>
      <geometry>
        <sphere radius="0.001"/>
      </geometry>
    </visual>
    <collision>
      <origin rpy="0 0 0" xyz="0 0 0"/>
      <geometry>
        <sphere radius="0.001"/>
      </geometry>
    </collision>
  </link>
  <joint name="base_camera_gyro_optical_joint" type="fixed">
    <origin rpy="-1.5707963267948966 0 -1.5707963267948966" xyz="0 0 0"/>
    <parent link="base_camera_gyro_frame"/>
    <child link="base_camera_gyro_optical_frame"/>
  </joint>
  <link name="base_camera_gyro_optical_frame">
    <inertial>
      <origin rpy="0 0 0" xyz="0 0 0"/>
      <mass value="0.01"/>
      <inertia ixx="1e-5" ixy="0" ixz="0" iyy="1e-5" iyz="0" izz="1e-5"/>
    </inertial>
    <visual>
      <origin rpy="0 0 0" xyz="0 0 0"/>
      <geometry>
        <sphere radius="0.001"/>
      </geometry>
    </visual>
    <collision>
      <origin rpy="0 0 0" xyz="0 0 0"/>
      <geometry>
        <sphere radius="0.001"/>
      </geometry>
    </collision>
  </link>
  <gazebo reference="base_camera">
    <sensor name="base_camera_realsense" type="multi_camera">
      <update_rate>30</update_rate>
      <always_on>1</always_on>
      <visualize>true</visualize>
      <plugin filename="libgazebo_ros_realsense_camera.so" name="gazebo_ros_realsense_camera">
        <depth_topic>depth/image_raw</depth_topic>
        <infra1_topic>infra1/image_raw</infra1_topic>
        <infra2_topic>infra2/image_raw</infra2_topic>
        <color_topic>color/image_raw</color_topic>
        <depth_camera_info_topic>depth/camera_info</depth_camera_info_topic>
        <infra1_camera_info_topic>infra1/camera_info</infra1_camera_info_topic>
        <infra2_camera_info_topic>infra2/camera_info</infra2_camera_info_topic>
        <color_camera_info_topic>color/camera_info</color_camera_info_topic>
        <point_cloud_topic>depth/points</point_cloud_topic>
        <enable_point_cloud>true</enable_point_cloud>
        <point_cloud_cutoff>0.5</point_cloud_cutoff>
        <range_min>0.1</range_min>
        <range_max>10.0</range_max>
        <robot_namespace>base_camera</robot_namespace>
        <depth_frame_name>base_camera_depth_optical_frame</depth_frame_name>
        <infra1_frame_name>base_camera_infra1_optical_frame</infra1_frame_name>
        <infra2_frame_name>base_camera_infra2_optical_frame</infra2_frame_name>
        <color_frame_name>base_camera_color_optical_frame</color_frame_name>
      </plugin>
      <!-- 깊이 카메라 설정 -->
      <camera name="depth">
        <horizontal_fov>1.4870205226991688</horizontal_fov>
        <image>
          <width>1280</width>
          <height>720</height>
          <format>R8G8B8</format>
        </image>
        <clip>
          <near>0.1</near>
          <far>10.0</far>
        </clip>
      </camera>
      <!-- 컬러 카메라 설정 -->
      <camera name="color">
        <horizontal_fov>1.2112585008840648</horizontal_fov>
        <image>
          <width>1280</width>
          <height>720</height>
          <format>R8G8B8</format>
        </image>
        <clip>
          <near>0.1</near>
          <far>10.0</far>
        </clip>
      </camera>
      <!-- 적외선 카메라 설정 -->
      <camera name="infra1">
        <horizontal_fov>1.4870205226991688</horizontal_fov>
        <image>
          <width>1280</width>
          <height>720</height>
          <format>L8</format>
        </image>
        <clip>
          <near>0.1</near>
          <far>10.0</far>
        </clip>
      </camera>
      <camera name="infra2">
        <horizontal_fov>1.4870205226991688</horizontal_fov>
        <image>
          <width>1280</width>
          <height>720</height>
          <format>L8</format>
        </image>
        <clip>
          <near>0.1</near>
          <far>10.0</far>
        </clip>
      </camera>
    </sensor>
  </gazebo>
  <joint name="base_arm_connector_joint" type="fixed">
    <origin rpy="0 0 0" xyz="0 0 0.0576"/>
    <parent link="base_body"/>
    <child link="base_arm_connector"/>
  </joint>
  <link name="base_arm_connector">
    <visual>
      <origin rpy="0 0 0" xyz="0 0 -0.0288"/>
      <geometry>
        <mesh filename="/home/research/hc_ws/install/mobile_manipulator/share/mobile_manipulator/meshes/base/base_arm_connector.stl"/>
      </geometry>
      <material name="">
        <color rgba="0.79216 0.81961 0.93333 1"/>
      </material>
    </visual>
    <collision>
      <origin rpy="0 0 0" xyz="0 0 -0.0288"/>
      <geometry>
        <mesh filename="/home/research/hc_ws/install/mobile_manipulator/share/mobile_manipulator/meshes/base/base_arm_connector.stl"/>
      </geometry>
    </collision>
    <inertial>
      <origin rpy="0 0 0" xyz="0 0 -0.0288"/>
      <mass value="0.3"/>
      <inertia ixx="0.000360509202" ixy="0.0" ixz="0.0" iyy="0.000360509202" iyz="0.0" izz="0.001062865206"/>
    </inertial>
  </link>
  <gazebo reference="base_arm_connector">
    <material>Kortex/Gray</material>
  </gazebo>
  <joint name="arm_base_joint" type="fixed">
    <origin rpy="0 0 0" xyz="0 0 0"/>
    <parent link="base_arm_connector"/>
    <child link="arm_base_link"/>
  </joint>
  <link name="arm_base_link">
    <visual>
      <origin rpy="0 0 0" xyz="0 0 0"/>
      <geometry>
        <mesh filename="/home/research/hc_ws/install/mobile_manipulator/share/mobile_manipulator/meshes/arm/base_link.STL"/>
      </geometry>
      <material name="">
        <color rgba="0.803 0.824 0.820 1"/>
      </material>
    </visual>
    <collision>
      <origin rpy="0 0 0" xyz="0 0 0"/>
      <geometry>
        <mesh filename="/home/research/hc_ws/install/mobile_manipulator/share/mobile_manipulator/meshes/arm/base_link.STL"/>
      </geometry>
    </collision>
    <inertial>
      <origin rpy="0 0 0" xyz="0.00244324 0.00015573 0.08616742"/>
      <mass value="1.14608471"/>
      <inertia ixx="0.00335854" ixy="3.9E-07" ixz="0.00010989" iyy="0.003311" iyz="1.91E-06" izz="0.00077158"/>
    </inertial>
  </link>
  <gazebo reference="arm_base_link">
    <material>Kortex/Gray</material>
  </gazebo>
  <joint name="arm_joint_1" type="revolute">
    <origin rpy="0 0 0" xyz="0 0 0.12825"/>
    <parent link="arm_base_link"/>
    <child link="arm_link_1"/>
    <axis xyz="0 0 1"/>
    <limit effort="10" lower="-2.69" upper="2.69" velocity="1.6"/>
  </joint>
  <link name="arm_link_1">
    <visual>
      <origin rpy="0 0 0" xyz="0 0 0"/>
      <geometry>
        <mesh filename="/home/research/hc_ws/install/mobile_manipulator/share/mobile_manipulator/meshes/arm/shoulder_link.STL"/>
      </geometry>
      <material name="">
        <color rgba="0.803 0.824 0.820 1"/>
      </material>
    </visual>
    <collision>
      <origin rpy="0 0 0" xyz="0 0 0"/>
      <geometry>
        <mesh filename="/home/research/hc_ws/install/mobile_manipulator/share/mobile_manipulator/meshes/arm/shoulder_link.STL"/>
      </geometry>
    </collision>
    <inertial>
      <origin rpy="0 0 0" xyz="2.477E-05 0.02213531 0.09937686"/>
      <mass value="0.95974404"/>
      <inertia ixx="0.00165947" ixy="2E-08" ixz="3.6E-07" iyy="0.00140355" iyz="0.00034927" izz="0.00089493"/>
    </inertial>
  </link>
  <gazebo reference="arm_link_1">
    <material>Kortex/Gray</material>
  </gazebo>
  <joint name="arm_joint_2" type="revolute">
    <origin rpy="1.5707963267948966 0 0" xyz="0 -0.03 0.115"/>
    <parent link="arm_link_1"/>
    <child link="arm_link_2"/>
    <axis xyz="0 0 1"/>
    <limit effort="14" lower="-2.69" upper="2.69" velocity="1.6"/>
  </joint>
  <link name="arm_link_2">
    <visual>
      <origin rpy="0 0 0" xyz="0 0 0"/>
      <geometry>
        <mesh filename="/home/research/hc_ws/install/mobile_manipulator/share/mobile_manipulator/meshes/arm/arm_link.STL"/>
      </geometry>
      <material name="">
        <color rgba="0.803 0.824 0.820 1"/>
      </material>
    </visual>
    <collision>
      <origin rpy="0 0 0" xyz="0 0 0"/>
      <geometry>
        <mesh filename="/home/research/hc_ws/install/mobile_manipulator/share/mobile_manipulator/meshes/arm/arm_link.STL"/>
      </geometry>
    </collision>
    <inertial>
      <origin rpy="0 0 0" xyz="0.02998299 0.21154808 0.0453031"/>
      <mass value="1.17756164"/>
      <inertia ixx="0.01149277" ixy="1E-06" ixz="1.6E-07" iyy="0.00102851" iyz="0.00140765" izz="0.01133492"/>
    </inertial>
  </link>
  <gazebo reference="arm_link_2">
    <material>Kortex/Gray</material>
  </gazebo>
  <joint name="arm_joint_3" type="revolute">
    <origin rpy="-3.141592653589793 0 0" xyz="0 0.28 0"/>
    <parent link="arm_link_2"/>
    <child link="arm_link_3"/>
    <axis xyz="0 0 1"/>
    <limit effort="10" lower="-2.69" upper="2.69" velocity="1.6"/>
  </joint>
  <link name="arm_link_3">
    <visual>
      <origin rpy="0 0 0" xyz="0 0 0"/>
      <geometry>
        <mesh filename="/home/research/hc_ws/install/mobile_manipulator/share/mobile_manipulator/meshes/arm/forearm_link.STL"/>
      </geometry>
      <material name="">
        <color rgba="0.803 0.824 0.820 1"/>
      </material>
    </visual>
    <collision>
      <origin rpy="0 0 0" xyz="0 0 0"/>
      <geometry>
        <mesh filename="/home/research/hc_ws/install/mobile_manipulator/share/mobile_manipulator/meshes/arm/forearm_link.STL"/>
      </geometry>
    </collision>
    <inertial>
      <origin rpy="0 0 0" xyz="0.0301559 0.09502206 0.0073555"/>
      <mass value="0.59767669"/>
      <inertia ixx="0.00163256" ixy="7.11E-06" ixz="1.54E-06" iyy="0.00029798" iyz="9.587E-05" izz="0.00169091"/>
    </inertial>
  </link>
  <gazebo reference="arm_link_3">
    <material>Kortex/Gray</material>
  </gazebo>
  <joint name="arm_joint_4" type="revolute">
    <origin rpy="1.5707963267948966 0 0" xyz="0 -0.14 0.02"/>
    <parent link="arm_link_3"/>
    <child link="arm_link_4"/>
    <axis xyz="0 0 1"/>
    <limit effort="7" lower="-2.59" upper="2.59" velocity="1.6"/>
  </joint>
  <link name="arm_link_4">
    <visual>
      <origin rpy="0 0 0" xyz="0 0 0"/>
      <geometry>
        <mesh filename="/home/research/hc_ws/install/mobile_manipulator/share/mobile_manipulator/meshes/arm/lower_wrist_link.STL"/>
      </geometry>
      <material name="">
        <color rgba="0.803 0.824 0.820 1"/>
      </material>
    </visual>
    <collision>
      <origin rpy="0 0 0" xyz="0 0 0"/>
      <geometry>
        <mesh filename="/home/research/hc_ws/install/mobile_manipulator/share/mobile_manipulator/meshes/arm/lower_wrist_link.STL"/>
      </geometry>
    </collision>
    <inertial>
      <origin rpy="0 0 0" xyz="0.00575149 0.01000443 0.08719207"/>
      <mass value="0.52693412"/>
      <inertia ixx="0.00069098" ixy="2.4E-07" ixz="0.00016483" iyy="0.00078519" iyz="7.4E-07" izz="0.00034115"/>
    </inertial>
  </link>
  <gazebo reference="arm_link_4">
    <material>Kortex/Gray</material>
  </gazebo>
  <joint name="arm_joint_5" type="revolute">
    <origin rpy="0 1.5707963267948966 0" xyz="0.0285 0 0.105"/>
    <parent link="arm_link_4"/>
    <child link="arm_link_5"/>
    <axis xyz="0 0 1"/>
    <limit effort="7" lower="-2.57" upper="2.57" velocity="1.6"/>
  </joint>
  <link name="arm_link_5">
    <visual>
      <origin rpy="0 0 0" xyz="0 0 0"/>
      <geometry>
        <mesh filename="/home/research/hc_ws/install/mobile_manipulator/share/mobile_manipulator/meshes/arm/upper_wrist_link.STL"/>
      </geometry>
      <material name="">
        <color rgba="0.803 0.824 0.820 1"/>
      </material>
    </visual>
    <collision>
      <origin rpy="0 0 0" xyz="0 0 0"/>
      <geometry>
        <mesh filename="/home/research/hc_ws/install/mobile_manipulator/share/mobile_manipulator/meshes/arm/upper_wrist_link.STL"/>
      </geometry>
    </collision>
    <inertial>
      <origin rpy="0 0 0" xyz="0.08056517 0.00980409 0.01872799"/>
      <mass value="0.58097325"/>
      <inertia ixx="0.00021268" ixy="5.21E-06" ixz="2.91E-06" iyy="0.00106371" iyz="1.1E-07" izz="0.00108465"/>
    </inertial>
  </link>
  <gazebo reference="arm_link_5">
    <material>Kortex/Gray</material>
  </gazebo>
  <joint name="arm_joint_6" type="revolute">
    <origin rpy="0 -1.5707963267948966 0" xyz="-0.105 0 0.0285"/>
    <parent link="arm_link_5"/>
    <child link="end_effector_link"/>
    <axis xyz="0 0 1"/>
    <limit effort="7" lower="-2.59" upper="2.59" velocity="3.2"/>
  </joint>
  <link name="end_effector_link">
    <inertial>
      <mass value="0.0001"/>
      <origin rpy="0 0 0" xyz="0 0 0"/>
      <inertia ixx="1e-6" ixy="0" ixz="0" iyy="1e-6" iyz="0" izz="1e-6"/>
    </inertial>
    <collision>
      <origin rpy="0 0 0" xyz="0 0 0"/>
      <geometry>
        <sphere radius="0.001"/>
      </geometry>
    </collision>
  </link>
  <joint name="tool_frame_joint" type="fixed">
    <origin rpy="0 0 -3.141592653589793" xyz="0 0 0.130"/>
    <parent link="end_effector_link"/>
    <child link="tool_frame"/>
  </joint>
  <link name="tool_frame">
    <inertial>
      <mass value="0.0001"/>
      <origin rpy="0 0 0" xyz="0 0 0"/>
      <inertia ixx="1e-6" ixy="0" ixz="0" iyy="1e-6" iyz="0" izz="1e-6"/>
    </inertial>
    <collision>
      <origin rpy="0 0 0" xyz="0 0 0"/>
      <geometry>
        <sphere radius="0.001"/>
      </geometry>
    </collision>
  </link>
  <joint name="camera_case_joint" type="fixed">
    <origin rpy="0 -1.5707963267948966 0" xyz="0 0 0.01794"/>
    <parent link="end_effector_link"/>
    <child link="camera_case_link"/>
  </joint>
  <link name="camera_case_link">
    <visual>
      <origin rpy="0 0 0" xyz="-0.01254 0 0"/>
      <geometry>
        <mesh filename="/home/research/hc_ws/install/mobile_manipulator/share/mobile_manipulator/meshes/arm/camera_case.stl"/>
      </geometry>
      <material name="">
        <color rgba="0 0 0 1"/>
      </material>
    </visual>
    <collision>
      <origin rpy="0 0 0" xyz="-0.01254 0 0"/>
      <geometry>
        <mesh filename="/home/research/hc_ws/install/mobile_manipulator/share/mobile_manipulator/meshes/arm/camera_case.stl"/>
      </geometry>
    </collision>
    <inertial>
      <origin rpy="0 0 0" xyz="-0.01254 0 0"/>
      <mass value="0.072"/>
      <inertia ixx="9.955494960000002e-05" ixy="0.0" ixz="0.0" iyy="2.8038549599999993e-05" iyz="0.0" izz="0.00012570648"/>
    </inertial>
  </link>
  <gazebo reference="camera_case_link">
    <material>Kortex/Black</material>
  </gazebo>
  <joint name="gripper_camera_joint" type="fixed">
    <origin ryp="1.5707963267948966 0 1.5707963267948966" xyz="0.02505 0 0.08203"/>
    <parent link="camera_case_link"/>
    <child link="gripper_camera"/>
  </joint>
  <link name="gripper_camera">
    <visual>
      <origin rpy="0 0 0" xyz="0 0 0"/>
      <geometry>
        <mesh filename="/home/research/hc_ws/install/mobile_manipulator/share/mobile_manipulator/meshes/arm/d435.dae"/>
      </geometry>
      <material name="aluminum">
        <color rgba="0.5 0.5 0.5 1"/>
      </material>
    </visual>
    <collision>
      <origin rpy="0 0 0" xyz="0 0 0"/>
      <geometry>
        <mesh filename="/home/research/hc_ws/install/mobile_manipulator/share/mobile_manipulator/meshes/arm/d435.dae"/>
      </geometry>
    </collision>
    <inertial>
      <origin rpy="0 0 0" xyz="0 0 0"/>
      <mass value="0.072"/>
      <inertia ixx="7.515015e-06" ixy="0.0" ixz="0.0" iyy="5.234999999999999e-05" iyz="0.0" izz="5.236501499999999e-05"/>
    </inertial>
  </link>
  <joint name="gripper_camera_depth_joint" type="fixed">
    <origin rpy="0 0 0" xyz="-0.00595 0.0175 0"/>
    <parent link="gripper_camera"/>
    <child link="gripper_camera_depth_frame"/>
  </joint>
  <link name="gripper_camera_depth_frame">
    <inertial>
      <origin rpy="0 0 0" xyz="0 0 0"/>
      <mass value="0.01"/>
      <inertia ixx="1e-5" ixy="0" ixz="0" iyy="1e-5" iyz="0" izz="1e-5"/>
    </inertial>
    <visual>
      <origin rpy="0 0 0" xyz="0 0 0"/>
      <geometry>
        <sphere radius="0.001"/>
      </geometry>
    </visual>
    <collision>
      <origin rpy="0 0 0" xyz="0 0 0"/>
      <geometry>
        <sphere radius="0.001"/>
      </geometry>
    </collision>
  </link>
  <joint name="gripper_camera_depth_optical_joint" type="fixed">
    <origin rpy="-1.5707963267948966 0 -1.5707963267948966" xyz="0 0 0"/>
    <parent link="gripper_camera_depth_frame"/>
    <child link="gripper_camera_depth_optical_frame"/>
  </joint>
  <link name="gripper_camera_depth_optical_frame">
    <inertial>
      <origin rpy="0 0 0" xyz="0 0 0"/>
      <mass value="0.01"/>
      <inertia ixx="1e-5" ixy="0" ixz="0" iyy="1e-5" iyz="0" izz="1e-5"/>
    </inertial>
    <visual>
      <origin rpy="0 0 0" xyz="0 0 0"/>
      <geometry>
        <sphere radius="0.001"/>
      </geometry>
    </visual>
    <collision>
      <origin rpy="0 0 0" xyz="0 0 0"/>
      <geometry>
        <sphere radius="0.001"/>
      </geometry>
    </collision>
  </link>
  <joint name="gripper_camera_infra1_joint" type="fixed">
    <origin rpy="0 0 0" xyz="0 0.0 0"/>
    <parent link="gripper_camera_depth_frame"/>
    <child link="gripper_camera_infra1_frame"/>
  </joint>
  <link name="gripper_camera_infra1_frame">
    <inertial>
      <origin rpy="0 0 0" xyz="0 0 0"/>
      <mass value="0.01"/>
      <inertia ixx="1e-5" ixy="0" ixz="0" iyy="1e-5" iyz="0" izz="1e-5"/>
    </inertial>
    <visual>
      <origin rpy="0 0 0" xyz="0 0 0"/>
      <geometry>
        <sphere radius="0.001"/>
      </geometry>
    </visual>
    <collision>
      <origin rpy="0 0 0" xyz="0 0 0"/>
      <geometry>
        <sphere radius="0.001"/>
      </geometry>
    </collision>
  </link>
  <joint name="gripper_camera_infra1_optical_joint" type="fixed">
    <origin rpy="-1.5707963267948966 0 -1.5707963267948966" xyz="0 0 0"/>
    <parent link="gripper_camera_infra1_frame"/>
    <child link="gripper_camera_infra1_optical_frame"/>
  </joint>
  <link name="gripper_camera_infra1_optical_frame">
    <inertial>
      <origin rpy="0 0 0" xyz="0 0 0"/>
      <mass value="0.01"/>
      <inertia ixx="1e-5" ixy="0" ixz="0" iyy="1e-5" iyz="0" izz="1e-5"/>
    </inertial>
    <visual>
      <origin rpy="0 0 0" xyz="0 0 0"/>
      <geometry>
        <sphere radius="0.001"/>
      </geometry>
    </visual>
    <collision>
      <origin rpy="0 0 0" xyz="0 0 0"/>
      <geometry>
        <sphere radius="0.001"/>
      </geometry>
    </collision>
  </link>
  <joint name="gripper_camera_infra2_joint" type="fixed">
    <origin rpy="0 0 0" xyz="0 -0.05 0"/>
    <parent link="gripper_camera_depth_frame"/>
    <child link="gripper_camera_infra2_frame"/>
  </joint>
  <link name="gripper_camera_infra2_frame">
    <inertial>
      <origin rpy="0 0 0" xyz="0 0 0"/>
      <mass value="0.01"/>
      <inertia ixx="1e-5" ixy="0" ixz="0" iyy="1e-5" iyz="0" izz="1e-5"/>
    </inertial>
    <visual>
      <origin rpy="0 0 0" xyz="0 0 0"/>
      <geometry>
        <sphere radius="0.001"/>
      </geometry>
    </visual>
    <collision>
      <origin rpy="0 0 0" xyz="0 0 0"/>
      <geometry>
        <sphere radius="0.001"/>
      </geometry>
    </collision>
  </link>
  <joint name="gripper_camera_infra2_optical_joint" type="fixed">
    <origin rpy="-1.5707963267948966 0 -1.5707963267948966" xyz="0 0 0"/>
    <parent link="gripper_camera_infra2_frame"/>
    <child link="gripper_camera_infra2_optical_frame"/>
  </joint>
  <link name="gripper_camera_infra2_optical_frame">
    <inertial>
      <origin rpy="0 0 0" xyz="0 0 0"/>
      <mass value="0.01"/>
      <inertia ixx="1e-5" ixy="0" ixz="0" iyy="1e-5" iyz="0" izz="1e-5"/>
    </inertial>
    <visual>
      <origin rpy="0 0 0" xyz="0 0 0"/>
      <geometry>
        <sphere radius="0.001"/>
      </geometry>
    </visual>
    <collision>
      <origin rpy="0 0 0" xyz="0 0 0"/>
      <geometry>
        <sphere radius="0.001"/>
      </geometry>
    </collision>
  </link>
  <joint name="gripper_camera_color_joint" type="fixed">
    <origin rpy="0 0 0" xyz="0 0.015 0"/>
    <parent link="gripper_camera_depth_frame"/>
    <child link="gripper_camera_color_frame"/>
  </joint>
  <link name="gripper_camera_color_frame">
    <inertial>
      <origin rpy="0 0 0" xyz="0 0 0"/>
      <mass value="0.01"/>
      <inertia ixx="1e-5" ixy="0" ixz="0" iyy="1e-5" iyz="0" izz="1e-5"/>
    </inertial>
    <visual>
      <origin rpy="0 0 0" xyz="0 0 0"/>
      <geometry>
        <sphere radius="0.001"/>
      </geometry>
    </visual>
    <collision>
      <origin rpy="0 0 0" xyz="0 0 0"/>
      <geometry>
        <sphere radius="0.001"/>
      </geometry>
    </collision>
  </link>
  <joint name="gripper_camera_color_optical_joint" type="fixed">
    <origin rpy="-1.5707963267948966 0 -1.5707963267948966" xyz="0 0 0"/>
    <parent link="gripper_camera_color_frame"/>
    <child link="gripper_camera_color_optical_frame"/>
  </joint>
  <link name="gripper_camera_color_optical_frame">
    <inertial>
      <origin rpy="0 0 0" xyz="0 0 0"/>
      <mass value="0.01"/>
      <inertia ixx="1e-5" ixy="0" ixz="0" iyy="1e-5" iyz="0" izz="1e-5"/>
    </inertial>
    <visual>
      <origin rpy="0 0 0" xyz="0 0 0"/>
      <geometry>
        <sphere radius="0.001"/>
      </geometry>
    </visual>
    <collision>
      <origin rpy="0 0 0" xyz="0 0 0"/>
      <geometry>
        <sphere radius="0.001"/>
      </geometry>
    </collision>
  </link>
  <joint name="gripper_camera_accel_joint" type="fixed">
    <origin rpy="0 0 0" xyz="-0.01174 -0.00552 0.0051"/>
    <parent link="gripper_camera_depth_frame"/>
    <child link="gripper_camera_accel_frame"/>
  </joint>
  <link name="gripper_camera_accel_frame">
    <inertial>
      <origin rpy="0 0 0" xyz="0 0 0"/>
      <mass value="0.01"/>
      <inertia ixx="1e-5" ixy="0" ixz="0" iyy="1e-5" iyz="0" izz="1e-5"/>
    </inertial>
    <visual>
      <origin rpy="0 0 0" xyz="0 0 0"/>
      <geometry>
        <sphere radius="0.001"/>
      </geometry>
    </visual>
    <collision>
      <origin rpy="0 0 0" xyz="0 0 0"/>
      <geometry>
        <sphere radius="0.001"/>
      </geometry>
    </collision>
  </link>
  <joint name="gripper_camera_accel_optical_joint" type="fixed">
    <origin rpy="-1.5707963267948966 0 -1.5707963267948966" xyz="0 0 0"/>
    <parent link="gripper_camera_accel_frame"/>
    <child link="gripper_camera_accel_optical_frame"/>
  </joint>
  <link name="gripper_camera_accel_optical_frame">
    <inertial>
      <origin rpy="0 0 0" xyz="0 0 0"/>
      <mass value="0.01"/>
      <inertia ixx="1e-5" ixy="0" ixz="0" iyy="1e-5" iyz="0" izz="1e-5"/>
    </inertial>
    <visual>
      <origin rpy="0 0 0" xyz="0 0 0"/>
      <geometry>
        <sphere radius="0.001"/>
      </geometry>
    </visual>
    <collision>
      <origin rpy="0 0 0" xyz="0 0 0"/>
      <geometry>
        <sphere radius="0.001"/>
      </geometry>
    </collision>
  </link>
  <joint name="gripper_camera_gyro_joint" type="fixed">
    <origin rpy="0 0 0" xyz="-0.01174 -0.00552 0.0051"/>
    <parent link="gripper_camera_depth_frame"/>
    <child link="gripper_camera_gyro_frame"/>
  </joint>
  <link name="gripper_camera_gyro_frame">
    <inertial>
      <origin rpy="0 0 0" xyz="0 0 0"/>
      <mass value="0.01"/>
      <inertia ixx="1e-5" ixy="0" ixz="0" iyy="1e-5" iyz="0" izz="1e-5"/>
    </inertial>
    <visual>
      <origin rpy="0 0 0" xyz="0 0 0"/>
      <geometry>
        <sphere radius="0.001"/>
      </geometry>
    </visual>
    <collision>
      <origin rpy="0 0 0" xyz="0 0 0"/>
      <geometry>
        <sphere radius="0.001"/>
      </geometry>
    </collision>
  </link>
  <joint name="gripper_camera_gyro_optical_joint" type="fixed">
    <origin rpy="-1.5707963267948966 0 -1.5707963267948966" xyz="0 0 0"/>
    <parent link="gripper_camera_gyro_frame"/>
    <child link="gripper_camera_gyro_optical_frame"/>
  </joint>
  <link name="gripper_camera_gyro_optical_frame">
    <inertial>
      <origin rpy="0 0 0" xyz="0 0 0"/>
      <mass value="0.01"/>
      <inertia ixx="1e-5" ixy="0" ixz="0" iyy="1e-5" iyz="0" izz="1e-5"/>
    </inertial>
    <visual>
      <origin rpy="0 0 0" xyz="0 0 0"/>
      <geometry>
        <sphere radius="0.001"/>
      </geometry>
    </visual>
    <collision>
      <origin rpy="0 0 0" xyz="0 0 0"/>
      <geometry>
        <sphere radius="0.001"/>
      </geometry>
    </collision>
  </link>
  <gazebo reference="gripper_camera">
    <sensor name="gripper_camera_realsense" type="multi_camera">
      <update_rate>30</update_rate>
      <always_on>1</always_on>
      <visualize>true</visualize>
      <plugin filename="libgazebo_ros_realsense_camera.so" name="gazebo_ros_realsense_camera">
        <depth_topic>depth/image_raw</depth_topic>
        <infra1_topic>infra1/image_raw</infra1_topic>
        <infra2_topic>infra2/image_raw</infra2_topic>
        <color_topic>color/image_raw</color_topic>
        <depth_camera_info_topic>depth/camera_info</depth_camera_info_topic>
        <infra1_camera_info_topic>infra1/camera_info</infra1_camera_info_topic>
        <infra2_camera_info_topic>infra2/camera_info</infra2_camera_info_topic>
        <color_camera_info_topic>color/camera_info</color_camera_info_topic>
        <point_cloud_topic>depth/points</point_cloud_topic>
        <enable_point_cloud>true</enable_point_cloud>
        <point_cloud_cutoff>0.5</point_cloud_cutoff>
        <range_min>0.1</range_min>
        <range_max>10.0</range_max>
        <robot_namespace>gripper_camera</robot_namespace>
        <depth_frame_name>gripper_camera_depth_optical_frame</depth_frame_name>
        <infra1_frame_name>gripper_camera_infra1_optical_frame</infra1_frame_name>
        <infra2_frame_name>gripper_camera_infra2_optical_frame</infra2_frame_name>
        <color_frame_name>gripper_camera_color_optical_frame</color_frame_name>
      </plugin>
      <!-- 깊이 카메라 설정 -->
      <camera name="depth">
        <horizontal_fov>1.4870205226991688</horizontal_fov>
        <image>
          <width>1280</width>
          <height>720</height>
          <format>R8G8B8</format>
        </image>
        <clip>
          <near>0.1</near>
          <far>10.0</far>
        </clip>
      </camera>
      <!-- 컬러 카메라 설정 -->
      <camera name="color">
        <horizontal_fov>1.2112585008840648</horizontal_fov>
        <image>
          <width>1280</width>
          <height>720</height>
          <format>R8G8B8</format>
        </image>
        <clip>
          <near>0.1</near>
          <far>10.0</far>
        </clip>
      </camera>
      <!-- 적외선 카메라 설정 -->
      <camera name="infra1">
        <horizontal_fov>1.4870205226991688</horizontal_fov>
        <image>
          <width>1280</width>
          <height>720</height>
          <format>L8</format>
        </image>
        <clip>
          <near>0.1</near>
          <far>10.0</far>
        </clip>
      </camera>
      <camera name="infra2">
        <horizontal_fov>1.4870205226991688</horizontal_fov>
        <image>
          <width>1280</width>
          <height>720</height>
          <format>L8</format>
        </image>
        <clip>
          <near>0.1</near>
          <far>10.0</far>
        </clip>
      </camera>
    </sensor>
  </gazebo>
  <joint name="gripper_base_joint" type="fixed">
    <origin rpy="0 0 0" xyz="0 0 0"/>
    <parent link="end_effector_link"/>
    <child link="gripper_base_link"/>
  </joint>
  <link name="gripper_base_link">
    <visual>
      <origin rpy="0 0 0" xyz="0 0 0"/>
      <geometry>
        <mesh filename="/home/research/hc_ws/install/mobile_manipulator/share/mobile_manipulator/meshes/arm/gripper_base_link.STL"/>
      </geometry>
      <material name="">
        <color rgba="0.803 0.824 0.820 1"/>
      </material>
    </visual>
    <collision>
      <origin rpy="0 0 0" xyz="0 0 0"/>
      <geometry>
        <mesh filename="/home/research/hc_ws/install/mobile_manipulator/share/mobile_manipulator/meshes/arm/gripper_base_link.STL"/>
      </geometry>
    </collision>
    <inertial>
      <origin rpy="0 0 0" xyz="4.03E-06 1.08E-05 0.041397"/>
      <mass value="0.1395"/>
      <inertia ixx="0.00011614" ixy="1E-08" ixz="4E-08" iyy="0.00010327" iyz="0" izz="9.707E-05"/>
    </inertial>
  </link>
  <gazebo reference="gripper_base_link">
    <material>Kortex/Gray</material>
  </gazebo>
  <joint name="right_finger_bottom_joint" type="revolute">
    <origin rpy="1.5707963267948966 0.7853981633974483 1.5707963267948966" xyz="0 -0.030501 0.070003"/>
    <parent link="gripper_base_link"/>
    <child link="right_finger_prox_link"/>
    <axis xyz="0 0 -1"/>
    <limit effort="50" lower="0.0" upper="0.85" velocity="0.6"/>
  </joint>
  <link name="right_finger_prox_link">
    <visual>
      <origin rpy="0 0 0" xyz="0 0 0"/>
      <geometry>
        <mesh filename="/home/research/hc_ws/install/mobile_manipulator/share/mobile_manipulator/meshes/arm/right_finger_prox_link.STL"/>
      </geometry>
      <material name="">
        <color rgba="0.803 0.824 0.820 1"/>
      </material>
    </visual>
    <collision>
      <origin rpy="0 0 0" xyz="0 0 0"/>
      <geometry>
        <mesh filename="/home/research/hc_ws/install/mobile_manipulator/share/mobile_manipulator/meshes/arm/right_finger_prox_link.STL"/>
      </geometry>
    </collision>
    <inertial>
      <origin rpy="0 0 0" xyz="0.020257 0.0063483 6.991E-05"/>
      <mass value="0.018385"/>
      <inertia ixx="2.29E-06" ixy="1.43E-06" ixz="0" iyy="4.56E-06" iyz="0" izz="4.77E-06"/>
    </inertial>
  </link>
  <gazebo reference="right_finger_prox_link">
    <material>Kortex/Gray</material>
  </gazebo>
  <joint name="right_finger_tip_joint" type="revolute">
    <origin rpy="0 0 0" xyz="-0.045636 0.020423 0"/>
    <parent link="right_finger_prox_link"/>
    <child link="right_finger_dist_link"/>
    <axis xyz="0 0 1"/>
    <limit effort="1000" lower="-0.50" upper="0.21" velocity="1000"/>
    <!--limit lower="-1.03" upper="0.21" effort="1000" velocity="1000" /-->
    <mimic joint="right_finger_bottom_joint" multiplier="-0.676" offset="0.149"/>
  </joint>
  <link name="right_finger_dist_link">
    <visual>
      <origin rpy="0 0 0" xyz="0 0 0"/>
      <geometry>
        <mesh filename="/home/research/hc_ws/install/mobile_manipulator/share/mobile_manipulator/meshes/arm/right_finger_dist_link.STL"/>
      </geometry>
      <material name="">
        <color rgba="0 0.055 0.525 1"/>
      </material>
    </visual>
    <collision>
      <origin rpy="0 0 0" xyz="0 0 0"/>
      <geometry>
        <mesh filename="/home/research/hc_ws/install/mobile_manipulator/share/mobile_manipulator/meshes/arm/right_finger_dist_link.STL"/>
      </geometry>
    </collision>
    <inertial>
      <origin rpy="0 0 0" xyz="0.018488 0.0011091 0"/>
      <mass value="0.010748"/>
      <inertia ixx="6.3E-07" ixy="3.2E-07" ixz="0" iyy="1.83E-06" iyz="0" izz="1.61E-06"/>
    </inertial>
  </link>
  <gazebo reference="right_finger_dist_link">
    <material>Kortex/Blue</material>
  </gazebo>
  <joint name="left_finger_bottom_joint" type="revolute">
    <origin rpy="-1.5707963267948966 0.7853981633974483 -1.5707963267948966" xyz="0 0.0305 0.070003"/>
    <parent link="gripper_base_link"/>
    <child link="left_finger_prox_link"/>
    <axis xyz="0 0 1"/>
    <limit effort="1000" lower="0.0" upper="0.85" velocity="1000"/>
    <mimic joint="right_finger_bottom_joint" multiplier="1.0" offset="0.0"/>
  </joint>
  <link name="left_finger_prox_link">
    <visual>
      <origin rpy="0 0 0" xyz="0 0 0"/>
      <geometry>
        <mesh filename="/home/research/hc_ws/install/mobile_manipulator/share/mobile_manipulator/meshes/arm/left_finger_prox_link.STL"/>
      </geometry>
      <material name="">
        <color rgba="0.803 0.824 0.820 1"/>
      </material>
    </visual>
    <collision>
      <origin rpy="0 0 0" xyz="0 0 0"/>
      <geometry>
        <mesh filename="/home/research/hc_ws/install/mobile_manipulator/share/mobile_manipulator/meshes/arm/left_finger_prox_link.STL"/>
      </geometry>
    </collision>
    <inertial>
      <origin rpy="0 0 0" xyz="0.020257 0.0063483 6.99E-05"/>
      <mass value="0.018385"/>
      <inertia ixx="2.29E-06" ixy="1.43E-06" ixz="0" iyy="4.56E-06" iyz="0" izz="4.77E-06"/>
    </inertial>
  </link>
  <gazebo reference="left_finger_prox_link">
    <material>Kortex/Gray</material>
  </gazebo>
  <joint name="left_finger_tip_joint" type="revolute">
    <origin rpy="0 0 0" xyz="-0.045636 -0.020423 6.9901E-05"/>
    <parent link="left_finger_prox_link"/>
    <child link="left_finger_dist_link"/>
    <axis xyz="0 0 -1"/>
    <limit effort="1000" lower="-0.50" upper="0.21" velocity="1000"/>
    <!--limit lower="-1.03" upper="0.21" effort="1000" velocity="1000" /-->
    <mimic joint="right_finger_bottom_joint" multiplier="-0.676" offset="0.149"/>
  </joint>
  <link name="left_finger_dist_link">
    <visual>
      <origin rpy="0 0 0" xyz="0 0 0"/>
      <geometry>
        <mesh filename="/home/research/hc_ws/install/mobile_manipulator/share/mobile_manipulator/meshes/arm/left_finger_dist_link.STL"/>
      </geometry>
      <material name="">
        <color rgba="0 0.055 0.525 1"/>
      </material>
    </visual>
    <collision>
      <origin rpy="0 0 0" xyz="0 0 0"/>
      <geometry>
        <mesh filename="/home/research/hc_ws/install/mobile_manipulator/share/mobile_manipulator/meshes/arm/left_finger_dist_link.STL"/>
      </geometry>
    </collision>
    <inertial>
      <origin rpy="0 0 0" xyz="-0.018488 0.0011091 0"/>
      <mass value="0.010748"/>
      <inertia ixx="6.3E-07" ixy="3.2E-07" ixz="0" iyy="1.83E-06" iyz="0" izz="1.61E-06"/>
    </inertial>
  </link>
  <gazebo reference="left_finger_dist_link">
    <material>Kortex/Blue</material>
  </gazebo>
  <gazebo reference="world"/>
  <gazebo>
    <plugin filename="libgazebo_ros2_control-system.so" name="gazebo_ros2_control::GazeboROS2ControlPlugin">
      <parameters>/home/research/hc_ws/install/mobile_manipulator/share/mobile_manipulator/config/ros2_control.yaml</parameters>
      <controller_manager_node_name>controller_manager</controller_manager_node_name>
    </plugin>
  </gazebo>
</robot>
