<?xml version="1.0" ?>
<robot name="mobile_manipulator">
  <link name="base_link"/>
  <joint name="base_body_joint" type="fixed">
    <origin rpy="0 0 0" xyz="0 0 0.29386"/>
    <parent link="base_link"/>
    <child link="base_body"/>
    <axis xyz="0 0 0"/>
  </joint>
  <link name="base_body">
    <visual>
      <origin rpy="0 0 0" xyz="0 0 0"/>
      <geometry>
        <mesh filename="package://mobile_manipulator/meshes/base/base_body.stl"/>
      </geometry>
      <material name="">
        <color rgba="1 1 1 1"/>
      </material>
    </visual>
    <collision>
      <origin rpy="0 0 0" xyz="0 0 0"/>
      <geometry>
        <mesh filename="package://mobile_manipulator/meshes/base/base_body.stl"/>
      </geometry>
    </collision>
    <inertial>
      <origin rpy="0 0 0" xyz="0 0 0"/>
      <mass value="24.3948952632956"/>
      <inertia ixx="0.4663503691671374" ixy="0.0" ixz="0.0" iyy="0.4663503691671374" iyz="0.0" izz="0.6505305403545494"/>
    </inertial>
  </link>
  <joint name="fl_joint" type="continuous">
    <origin rpy="-1.5707963267948966 0 0" xyz="0.05 0.127547 -0.23636000000000001 "/>
    <parent link="base_body"/>
    <child link="fl_wheel"/>
    <axis xyz="0 0 1"/>
  </joint>
  <link name="fl_wheel">
    <visual>
      <origin rpy="1.5707963267948966 0 0" xyz="0 0 0"/>
      <geometry>
        <mesh filename="package://mobile_manipulator/meshes/base/front_wheel.stl"/>
      </geometry>
      <material name="">
        <color rgba="0.5 0.5 0.5 1"/>
      </material>
    </visual>
    <collision>
      <origin rpy="1.5707963267948966 0 0" xyz="0 0 0"/>
      <geometry>
        <mesh filename="package://mobile_manipulator/meshes/base/front_wheel.stl"/>
      </geometry>
    </collision>
    <inertial>
      <origin rpy="1.5707963267948966 0 0" xyz="0 0 0"/>
      <mass value="1.0568406891164"/>
      <inertia ixx="0.001430677286032044" ixy="0.0" ixz="0.0" iyy="0.001430677286032044" iyz="0.0" izz="0.0017470897641955487"/>
    </inertial>
  </link>
  <joint name="fr_joint" type="continuous">
    <origin rpy="1.5707963267948966 0 0" xyz="0.05 -0.127547 -0.23636000000000001"/>
    <parent link="base_body"/>
    <child link="fr_wheel"/>
    <axis xyz="0 0 1"/>
  </joint>
  <link name="fr_wheel">
    <visual>
      <origin rpy="-1.5707963267948966 0 0" xyz="0 0 0"/>
      <geometry>
        <mesh filename="package://mobile_manipulator/meshes/base/front_wheel.stl"/>
      </geometry>
      <material name="">
        <color rgba="0.5 0.5 0.5 1"/>
      </material>
    </visual>
    <collision>
      <origin rpy="-1.5707963267948966 0 0" xyz="0 0 0"/>
      <geometry>
        <mesh filename="package://mobile_manipulator/meshes/base/front_wheel.stl"/>
      </geometry>
    </collision>
    <inertial>
      <origin rpy="-1.5707963267948966 0 0" xyz="0 0 0"/>
      <mass value="1.0568406891164"/>
      <inertia ixx="0.001430677286032044" ixy="0.0" ixz="0.0" iyy="0.001430677286032044" iyz="0.0" izz="0.0017470897641955487"/>
    </inertial>
  </link>
  <joint name="rl_bracket_joint" type="continuous">
    <origin rpy="0 0 0" xyz="-0.17043 0.125 -0.21606000000000003"/>
    <parent link="base_body"/>
    <child link="rl_bracket"/>
    <axis xyz="0 0 1"/>
  </joint>
  <link name="rl_bracket">
    <visual>
      <origin rpy="0 0 1.5707963267948966" xyz="0 0 0"/>
      <geometry>
        <mesh filename="package://mobile_manipulator/meshes/base/rear_wheel_bracket.stl"/>
      </geometry>
      <material name="">
        <color rgba="0.5 0.5 0.5 1"/>
      </material>
    </visual>
    <collision>
      <origin rpy="0 0 1.5707963267948966" xyz="0 0 0"/>
      <geometry>
        <mesh filename="package://mobile_manipulator/meshes/base/rear_wheel_bracket.stl"/>
      </geometry>
    </collision>
    <inertial>
      <origin rpy="0 0 1.5707963267948966" xyz="0 0 0"/>
      <mass value="0.0211573699864"/>
      <inertia ixx="4.147003197609298e-06" ixy="0.0" ixz="0.0" iyy="4.147003197609298e-06" iyz="0.0" izz="1.05786849932e-06"/>
    </inertial>
  </link>
  <joint name="rl_wheel_joint" type="continuous">
    <origin rpy="-1.5707963267948966 0 0" xyz="-0.027 0 -0.0453"/>
    <parent link="rl_bracket"/>
    <child link="rl_wheel"/>
    <axis xyz="0 0 1"/>
  </joint>
  <link name="rl_wheel">
    <visual>
      <origin rpy="0 -1.5707963267948966 0" xyz="0 0 0"/>
      <geometry>
        <mesh filename="package://mobile_manipulator/meshes/base/rear_wheel.stl"/>
      </geometry>
      <material name="">
        <color rgba="0.5 0.5 0.5 1"/>
      </material>
    </visual>
    <collision>
      <origin rpy="0 -1.5707963267948966 0" xyz="0 0 0"/>
      <geometry>
        <mesh filename="package://mobile_manipulator/meshes/base/rear_wheel.stl"/>
      </geometry>
    </collision>
    <inertial>
      <origin rpy="0 -1.5707963267948966 0" xyz="0 0 0"/>
      <mass value="0.0920111896829"/>
      <inertia ixx="2.812178254208805e-05" ixy="0.0" ixz="0.0" iyy="2.812178254208805e-05" iyz="0.0" izz="4.859340955128157e-05"/>
    </inertial>
  </link>
  <joint name="rr_bracekt_joint" type="continuous">
    <origin rpy="0 0 0" xyz="-0.17043 -0.125 -0.21606000000000003"/>
    <parent link="base_body"/>
    <child link="rr_bracket"/>
    <axis xyz="0 0 1"/>
  </joint>
  <link name="rr_bracket">
    <visual>
      <origin rpy="0 0 1.5707963267948966" xyz="0 0 0"/>
      <geometry>
        <mesh filename="package://mobile_manipulator/meshes/base/rear_wheel_bracket.stl"/>
      </geometry>
      <material name="">
        <color rgba="0.5 0.5 0.5 1"/>
      </material>
    </visual>
    <collision>
      <origin rpy="0 0 1.5707963267948966" xyz="0 0 0"/>
      <geometry>
        <mesh filename="package://mobile_manipulator/meshes/base/rear_wheel_bracket.stl"/>
      </geometry>
    </collision>
    <inertial>
      <origin rpy="0 0 1.5707963267948966" xyz="0 0 0"/>
      <mass value="0.0211573699864"/>
      <inertia ixx="4.147003197609298e-06" ixy="0.0" ixz="0.0" iyy="4.147003197609298e-06" iyz="0.0" izz="1.05786849932e-06"/>
    </inertial>
  </link>
  <joint name="rr_wheel_joint" type="continuous">
    <origin rpy="1.5707963267948966 0 0" xyz="-0.027 0 -0.0453"/>
    <parent link="rr_bracket"/>
    <child link="rr_wheel"/>
    <axis xyz="0 0 1"/>
  </joint>
  <link name="rr_wheel">
    <visual>
      <origin rpy="0 1.5707963267948966 0" xyz="0 0 0"/>
      <geometry>
        <mesh filename="package://mobile_manipulator/meshes/base/rear_wheel.stl"/>
      </geometry>
      <material name="">
        <color rgba="0.5 0.5 0.5 1"/>
      </material>
    </visual>
    <collision>
      <origin rpy="0 1.5707963267948966 0" xyz="0 0 0"/>
      <geometry>
        <mesh filename="package://mobile_manipulator/meshes/base/rear_wheel.stl"/>
      </geometry>
    </collision>
    <inertial>
      <origin rpy="0 1.5707963267948966 0" xyz="0 0 0"/>
      <mass value="0.0920111896829"/>
      <inertia ixx="2.812178254208805e-05" ixy="0.0" ixz="0.0" iyy="2.812178254208805e-05" iyz="0.0" izz="4.859340955128157e-05"/>
    </inertial>
  </link>
  <joint name="laser_joint" type="fixed">
    <origin rpy="0 0 0" xyz="0.04517 0 -0.1053"/>
    <parent link="base_body"/>
    <child link="laser_Link"/>
    <axis xyz="0 0 0"/>
  </joint>
  <link name="laser_Link">
    <visual>
      <origin rpy="0 0 0" xyz="0 0 0"/>
      <geometry>
        <mesh filename="package://mobile_manipulator/meshes/base/lidar.stl"/>
      </geometry>
      <material name="">
        <color rgba="1 0.6 0 1"/>
      </material>
    </visual>
    <collision>
      <origin rpy="0 0 0" xyz="0 0 0"/>
      <geometry>
        <mesh filename="package://mobile_manipulator/meshes/base/lidar.stl"/>
      </geometry>
    </collision>
    <inertial>
      <origin rpy="0 0 0" xyz="0 0 0"/>
      <mass value="0.1071556446529"/>
      <inertia ixx="4.4109103083067026e-05" ixy="0.0" ixz="0.0" iyy="4.4109103083067026e-05" iyz="0.0" izz="8.10744965226074e-05"/>
    </inertial>
  </link>
  <joint name="camera_joint" type="fixed">
    <origin rpy="0 0 0" xyz="0.115 0 -0.04565"/>
    <parent link="base_body"/>
    <child link="camera_link"/>
    <axis xyz="0 0 0"/>
  </joint>
  <link name="camera_link">
    <visual>
      <origin rpy="0 0 0" xyz="0 0 0"/>
      <geometry>
        <mesh filename="package://mobile_manipulator/meshes/base/camera.stl"/>
      </geometry>
      <material name="">
        <color rgba="0.79216 0.81961 0.93333 1"/>
      </material>
    </visual>
    <collision>
      <origin rpy="0 0 0" xyz="0 0 0"/>
      <geometry>
        <mesh filename="package://mobile_manipulator/meshes/base/camera.stl"/>
      </geometry>
    </collision>
    <inertial>
      <origin rpy="-1.5707963267948966 0 0" xyz="0 0 0"/>
      <mass value="0.233324892864"/>
      <inertia ixx="0.00016100370156491112" ixy="0.0" ixz="0.0" iyy="0.00016100370156491112" iyz="0.0" izz="1.8668616334164716e-05"/>
    </inertial>
  </link>
  <joint name="base_arm_connector_joint" type="fixed">
    <origin rpy="0 0 0" xyz="0 0 0.0576"/>
    <parent link="base_body"/>
    <child link="base_arm_connector"/>
    <axis xyz="0 0 0"/>
  </joint>
  <link name="base_arm_connector">
    <visual>
      <origin rpy="0 0 0" xyz="0 0 -0.0288"/>
      <geometry>
        <mesh filename="package://mobile_manipulator/meshes/base/base_arm_connector.stl"/>
      </geometry>
      <material name="">
        <color rgba="0.79216 0.81961 0.93333 1"/>
      </material>
    </visual>
    <collision>
      <origin rpy="0 0 0" xyz="0 0 -0.0288"/>
      <geometry>
        <mesh filename="package://mobile_manipulator/meshes/base/base_arm_connector.stl"/>
      </geometry>
    </collision>
    <inertial>
      <origin rpy="0 0 0" xyz="0 0 -0.0288"/>
      <mass value="0.453507105351"/>
      <inertia ixx="0.0005449782821713965" ixy="0.0" ixz="0.0" iyy="0.0005449782821713965" iyz="0.0" izz="0.0016067230765045143"/>
    </inertial>
  </link>
  <gazebo reference="base_arm_connector">
    <material>Kortex/Gray</material>
  </gazebo>
  <joint name="arm_base_joint" type="fixed">
    <origin rpy="0 0 0" xyz="0 0 0"/>
    <parent link="base_arm_connector"/>
    <child link="arm_base_link"/>
  </joint>
  <link name="arm_base_link">
    <visual>
      <origin rpy="0 0 0" xyz="0 0 0"/>
      <geometry>
        <mesh filename="package://mobile_manipulator/meshes/arm/base_link.STL"/>
      </geometry>
      <material name="">
        <color rgba="0.803 0.824 0.820 1"/>
      </material>
    </visual>
    <collision>
      <origin rpy="0 0 0" xyz="0 0 0"/>
      <geometry>
        <mesh filename="package://mobile_manipulator/meshes/arm/base_link.STL"/>
      </geometry>
    </collision>
    <inertial>
      <origin rpy="0 0 0" xyz="0.00244324 0.00015573 0.08616742"/>
      <mass value="1.14608471"/>
      <inertia ixx="0.00335854" ixy="3.9E-07" ixz="0.00010989" iyy="0.003311" iyz="1.91E-06" izz="0.00077158"/>
    </inertial>
  </link>
  <gazebo reference="arm_base_link">
    <material>Kortex/Gray</material>
  </gazebo>
  <joint name="arm_joint_1" type="revolute">
    <origin rpy="0 0 0" xyz="0 0 0.12825"/>
    <parent link="arm_base_link"/>
    <child link="arm_link_1"/>
    <axis xyz="0 0 1"/>
    <limit effort="10" lower="-2.69" upper="2.69" velocity="1.6"/>
  </joint>
  <link name="arm_link_1">
    <visual>
      <origin rpy="0 0 0" xyz="0 0 0"/>
      <geometry>
        <mesh filename="package://mobile_manipulator/meshes/arm/shoulder_link.STL"/>
      </geometry>
      <material name="">
        <color rgba="0.803 0.824 0.820 1"/>
      </material>
    </visual>
    <collision>
      <origin rpy="0 0 0" xyz="0 0 0"/>
      <geometry>
        <mesh filename="package://mobile_manipulator/meshes/arm/shoulder_link.STL"/>
      </geometry>
    </collision>
    <inertial>
      <origin rpy="0 0 0" xyz="2.477E-05 0.02213531 0.09937686"/>
      <mass value="0.95974404"/>
      <inertia ixx="0.00165947" ixy="2E-08" ixz="3.6E-07" iyy="0.00140355" iyz="0.00034927" izz="0.00089493"/>
    </inertial>
  </link>
  <gazebo reference="arm_link_1">
    <material>Kortex/Gray</material>
  </gazebo>
  <joint name="arm_joint_2" type="revolute">
    <origin rpy="1.5708 0 0" xyz="0 -0.03 0.115"/>
    <parent link="arm_link_1"/>
    <child link="arm_link_2"/>
    <axis xyz="0 0 1"/>
    <limit effort="14" lower="-2.69" upper="2.69" velocity="1.6"/>
  </joint>
  <link name="arm_link_2">
    <inertial>
      <origin rpy="0 0 0" xyz="0.02998299 0.21154808 0.0453031"/>
      <mass value="1.17756164"/>
      <inertia ixx="0.01149277" ixy="1E-06" ixz="1.6E-07" iyy="0.00102851" iyz="0.00140765" izz="0.01133492"/>
    </inertial>
    <visual>
      <origin rpy="0 0 0" xyz="0 0 0"/>
      <geometry>
        <mesh filename="package://mobile_manipulator/meshes/arm/arm_link.STL"/>
      </geometry>
      <material name="">
        <color rgba="0.803 0.824 0.820 1"/>
      </material>
    </visual>
    <collision>
      <origin rpy="0 0 0" xyz="0 0 0"/>
      <geometry>
        <mesh filename="package://mobile_manipulator/meshes/arm/arm_link.STL"/>
      </geometry>
    </collision>
  </link>
  <gazebo reference="arm_link_2">
    <material>Kortex/Gray</material>
  </gazebo>
  <joint name="arm_joint_3" type="revolute">
    <origin rpy="-3.1416 0 0" xyz="0 0.28 0"/>
    <parent link="arm_link_2"/>
    <child link="arm_link_3"/>
    <axis xyz="0 0 1"/>
    <limit effort="10" lower="-2.69" upper="2.69" velocity="1.6"/>
  </joint>
  <link name="arm_link_3">
    <inertial>
      <origin rpy="0 0 0" xyz="0.0301559 0.09502206 0.0073555"/>
      <mass value="0.59767669"/>
      <inertia ixx="0.00163256" ixy="7.11E-06" ixz="1.54E-06" iyy="0.00029798" iyz="9.587E-05" izz="0.00169091"/>
    </inertial>
    <visual>
      <origin rpy="0 0 0" xyz="0 0 0"/>
      <geometry>
        <mesh filename="package://mobile_manipulator/meshes/arm/forearm_link.STL"/>
      </geometry>
      <material name="">
        <color rgba="0.803 0.824 0.820 1"/>
      </material>
    </visual>
    <collision>
      <origin rpy="0 0 0" xyz="0 0 0"/>
      <geometry>
        <mesh filename="package://mobile_manipulator/meshes/arm/forearm_link.STL"/>
      </geometry>
    </collision>
  </link>
  <gazebo reference="arm_link_3">
    <material>Kortex/Gray</material>
  </gazebo>
  <joint name="arm_joint_4" type="revolute">
    <origin rpy="1.5708 0 0" xyz="0 -0.14 0.02"/>
    <parent link="arm_link_3"/>
    <child link="arm_link_4"/>
    <axis xyz="0 0 1"/>
    <limit effort="7" lower="-2.59" upper="2.59" velocity="1.6"/>
  </joint>
  <link name="arm_link_4">
    <inertial>
      <origin rpy="0 0 0" xyz="0.00575149 0.01000443 0.08719207"/>
      <mass value="0.52693412"/>
      <inertia ixx="0.00069098" ixy="2.4E-07" ixz="0.00016483" iyy="0.00078519" iyz="7.4E-07" izz="0.00034115"/>
    </inertial>
    <visual>
      <origin rpy="0 0 0" xyz="0 0 0"/>
      <geometry>
        <mesh filename="package://mobile_manipulator/meshes/arm/lower_wrist_link.STL"/>
      </geometry>
      <material name="">
        <color rgba="0.803 0.824 0.820 1"/>
      </material>
    </visual>
    <collision>
      <origin rpy="0 0 0" xyz="0 0 0"/>
      <geometry>
        <mesh filename="package://mobile_manipulator/meshes/arm/lower_wrist_link.STL"/>
      </geometry>
    </collision>
  </link>
  <gazebo reference="arm_link_4">
    <material>Kortex/Gray</material>
  </gazebo>
  <joint name="arm_joint_5" type="revolute">
    <origin rpy="0 1.5708 0" xyz="0.0285 0 0.105"/>
    <parent link="arm_link_4"/>
    <child link="arm_link_5"/>
    <axis xyz="0 0 1"/>
    <limit effort="7" lower="-2.57" upper="2.57" velocity="1.6"/>
  </joint>
  <link name="arm_link_5">
    <inertial>
      <origin rpy="0 0 0" xyz="0.08056517 0.00980409 0.01872799"/>
      <mass value="0.58097325"/>
      <inertia ixx="0.00021268" ixy="5.21E-06" ixz="2.91E-06" iyy="0.00106371" iyz="1.1E-07" izz="0.00108465"/>
    </inertial>
    <visual>
      <origin rpy="0 0 0" xyz="0 0 0"/>
      <geometry>
        <mesh filename="package://mobile_manipulator/meshes/arm/upper_wrist_link.STL"/>
      </geometry>
      <material name="">
        <color rgba="0.803 0.824 0.820 1"/>
      </material>
    </visual>
    <collision>
      <origin rpy="0 0 0" xyz="0 0 0"/>
      <geometry>
        <mesh filename="package://mobile_manipulator/meshes/arm/upper_wrist_link.STL"/>
      </geometry>
    </collision>
  </link>
  <gazebo reference="arm_link_5">
    <material>Kortex/Gray</material>
  </gazebo>
  <joint name="arm_joint_6" type="revolute">
    <origin rpy="0 -1.5708 0" xyz="-0.105 0 0.0285"/>
    <parent link="arm_link_5"/>
    <child link="end_effector_link"/>
    <axis xyz="0 0 1"/>
    <limit effort="7" lower="-2.59" upper="2.59" velocity="3.2"/>
  </joint>
  <link name="end_effector_link"/>
  <!-- 그냥 tcp joint를 사용하려면 tool_frame이라는 링크가 있어야 한다고 해서 추가함 -->
  <joint name="tool_frame_joint" type="fixed">
    <origin rpy="0 0 1.57079632679" xyz="0 0 0.130"/>
    <parent link="end_effector_link"/>
    <child link="tool_frame"/>
    <axis xyz="0 0 0"/>
  </joint>
  <link name="tool_frame"/>
  <joint name="gripper_base_joint" type="fixed">
    <origin rpy="0 0 0" xyz="0 0 0"/>
    <parent link="end_effector_link"/>
    <child link="gripper_base_link"/>
    <axis xyz="0 0 0"/>
  </joint>
  <link name="gripper_base_link">
    <inertial>
      <origin rpy="0 0 0" xyz="4.03E-06 1.08E-05 0.041397"/>
      <mass value="0.1395"/>
      <inertia ixx="0.00011614" ixy="1E-08" ixz="4E-08" iyy="0.00010327" iyz="0" izz="9.707E-05"/>
    </inertial>
    <visual>
      <origin rpy="0 0 0" xyz="0 0 0"/>
      <geometry>
        <mesh filename="package://mobile_manipulator/meshes/gripper/gripper_base_link.STL"/>
      </geometry>
      <material name="">
        <color rgba="0.803 0.824 0.820 1"/>
      </material>
    </visual>
    <collision>
      <origin rpy="0 0 0" xyz="0 0 0"/>
      <geometry>
        <mesh filename="package://mobile_manipulator/meshes/gripper/gripper_base_link.STL"/>
      </geometry>
    </collision>
  </link>
  <gazebo reference="gripper_base_link">
    <material>Kortex/Gray</material>
  </gazebo>
  <joint name="right_finger_bottom_joint" type="revolute">
    <origin rpy="1.571 0.611 1.571" xyz="0 -0.030501 0.070003"/>
    <parent link="gripper_base_link"/>
    <child link="right_finger_prox_link"/>
    <axis xyz="0 0 -1"/>
    <limit effort="50" lower="0.0" upper="0.85" velocity="0.6"/>
  </joint>
  <link name="right_finger_prox_link">
    <inertial>
      <origin rpy="0 0 0" xyz="0.020257 0.0063483 6.991E-05"/>
      <mass value="0.018385"/>
      <inertia ixx="2.29E-06" ixy="1.43E-06" ixz="0" iyy="4.56E-06" iyz="0" izz="4.77E-06"/>
    </inertial>
    <visual>
      <origin rpy="0 0 0" xyz="0 0 0"/>
      <geometry>
        <mesh filename="package://mobile_manipulator/meshes/gripper/right_finger_prox_link.STL"/>
      </geometry>
      <material name="">
        <color rgba="0.803 0.824 0.820 1"/>
      </material>
    </visual>
    <collision>
      <origin rpy="0 0 0" xyz="0 0 0"/>
      <geometry>
        <mesh filename="package://mobile_manipulator/meshes/gripper/right_finger_prox_link.STL"/>
      </geometry>
    </collision>
  </link>
  <gazebo reference="right_finger_prox_link">
    <material>Kortex/Gray</material>
  </gazebo>
  <joint name="right_finger_tip_joint" type="revolute">
    <origin rpy="0 0 0" xyz="-0.045636 0.020423 0"/>
    <parent link="right_finger_prox_link"/>
    <child link="right_finger_dist_link"/>
    <axis xyz="0 0 1"/>
    <limit effort="1000" lower="-0.50" upper="0.21" velocity="1000"/>
    <!--limit lower="-1.03" upper="0.21" effort="1000" velocity="1000" /-->
    <mimic joint="right_finger_bottom_joint" multiplier="-0.676" offset="0.149"/>
  </joint>
  <link name="right_finger_dist_link">
    <inertial>
      <origin rpy="0 0 0" xyz="0.018488 0.0011091 0"/>
      <mass value="0.010748"/>
      <inertia ixx="6.3E-07" ixy="3.2E-07" ixz="0" iyy="1.83E-06" iyz="0" izz="1.61E-06"/>
    </inertial>
    <visual>
      <origin rpy="0 0 0" xyz="0 0 0"/>
      <geometry>
        <mesh filename="package://mobile_manipulator/meshes/gripper/right_finger_dist_link.STL"/>
      </geometry>
      <material name="">
        <color rgba="0 0.055 0.525 1"/>
      </material>
    </visual>
    <collision>
      <origin rpy="0 0 0" xyz="0 0 0"/>
      <geometry>
        <mesh filename="package://mobile_manipulator/meshes/gripper/right_finger_dist_link.STL"/>
      </geometry>
    </collision>
  </link>
  <gazebo reference="right_finger_dist_link">
    <material>Kortex/Blue</material>
  </gazebo>
  <joint name="left_finger_bottom_joint" type="revolute">
    <origin rpy="-1.571 0.611 -1.571" xyz="0 0.0305 0.070003"/>
    <parent link="gripper_base_link"/>
    <child link="left_finger_prox_link"/>
    <axis xyz="0 0 1"/>
    <limit effort="1000" lower="0.0" upper="0.85" velocity="1000"/>
    <mimic joint="right_finger_bottom_joint" multiplier="1.0" offset="0.0"/>
  </joint>
  <link name="left_finger_prox_link">
    <inertial>
      <origin rpy="0 0 0" xyz="0.020257 0.0063483 6.99E-05"/>
      <mass value="0.018385"/>
      <inertia ixx="2.29E-06" ixy="1.43E-06" ixz="0" iyy="4.56E-06" iyz="0" izz="4.77E-06"/>
    </inertial>
    <visual>
      <origin rpy="0 0 0" xyz="0 0 0"/>
      <geometry>
        <mesh filename="package://mobile_manipulator/meshes/gripper/left_finger_prox_link.STL"/>
      </geometry>
      <material name="">
        <color rgba="0.803 0.824 0.820 1"/>
      </material>
    </visual>
    <collision>
      <origin rpy="0 0 0" xyz="0 0 0"/>
      <geometry>
        <mesh filename="package://mobile_manipulator/meshes/gripper/left_finger_prox_link.STL"/>
      </geometry>
    </collision>
  </link>
  <gazebo reference="left_finger_prox_link">
    <material>Kortex/Gray</material>
  </gazebo>
  <joint name="left_finger_tip_joint" type="revolute">
    <origin rpy="0 0 0" xyz="-0.045636 -0.020423 6.9901E-05"/>
    <parent link="left_finger_prox_link"/>
    <child link="left_finger_dist_link"/>
    <axis xyz="0 0 -1"/>
    <limit effort="1000" lower="-0.50" upper="0.21" velocity="1000"/>
    <!--limit lower="-1.03" upper="0.21" effort="1000" velocity="1000" /-->
    <mimic joint="right_finger_bottom_joint" multiplier="-0.676" offset="0.149"/>
  </joint>
  <link name="left_finger_dist_link">
    <inertial>
      <origin rpy="0 0 0" xyz="-0.018488 0.0011091 0"/>
      <mass value="0.010748"/>
      <inertia ixx="6.3E-07" ixy="3.2E-07" ixz="0" iyy="1.83E-06" iyz="0" izz="1.61E-06"/>
    </inertial>
    <visual>
      <origin rpy="0 0 0" xyz="0 0 0"/>
      <geometry>
        <mesh filename="package://mobile_manipulator/meshes/gripper/left_finger_dist_link.STL"/>
      </geometry>
      <material name="">
        <color rgba="0 0.055 0.525 1"/>
      </material>
    </visual>
    <collision>
      <origin rpy="0 0 0" xyz="0 0 0"/>
      <geometry>
        <mesh filename="package://mobile_manipulator/meshes/gripper/left_finger_dist_link.STL"/>
      </geometry>
    </collision>
  </link>
  <gazebo reference="left_finger_dist_link">
    <material>Kortex/Blue</material>
  </gazebo>
  <!-- </xacro:macro> -->
</robot>
